2020-01-11 15:05:30,569 INFO: Microblog startup [in C:\Dev\microblog\app\__init__.py:41]
2020-01-11 15:05:40,965 ERROR: Exception on /edit_profile [POST] [in c:\python36\lib\site-packages\flask\app.py:1891]
Traceback (most recent call last):
  File "c:\python36\lib\site-packages\sqlalchemy\orm\base.py", line 399, in _entity_descriptor
    return getattr(entity, key)
AttributeError: type object 'User' has no attribute 'usename'

During handling of the above exception, another exception occurred:

Traceback (most recent call last):
  File "c:\python36\lib\site-packages\flask\app.py", line 2446, in wsgi_app
    response = self.full_dispatch_request()
  File "c:\python36\lib\site-packages\flask\app.py", line 1951, in full_dispatch_request
    rv = self.handle_user_exception(e)
  File "c:\python36\lib\site-packages\flask\app.py", line 1820, in handle_user_exception
    reraise(exc_type, exc_value, tb)
  File "c:\python36\lib\site-packages\flask\_compat.py", line 39, in reraise
    raise value
  File "c:\python36\lib\site-packages\flask\app.py", line 1949, in full_dispatch_request
    rv = self.dispatch_request()
  File "c:\python36\lib\site-packages\flask\app.py", line 1935, in dispatch_request
    return self.view_functions[rule.endpoint](**req.view_args)
  File "c:\python36\lib\site-packages\flask_login\utils.py", line 261, in decorated_view
    return func(*args, **kwargs)
  File "C:\Dev\microblog\app\routes.py", line 89, in edit_profile
    if form.validate_on_submit():
  File "c:\python36\lib\site-packages\flask_wtf\form.py", line 101, in validate_on_submit
    return self.is_submitted() and self.validate()
  File "c:\python36\lib\site-packages\wtforms\form.py", line 310, in validate
    return super(Form, self).validate(extra)
  File "c:\python36\lib\site-packages\wtforms\form.py", line 152, in validate
    if not field.validate(self, extra):
  File "c:\python36\lib\site-packages\wtforms\fields\core.py", line 206, in validate
    stop_validation = self._run_validation_chain(form, chain)
  File "c:\python36\lib\site-packages\wtforms\fields\core.py", line 226, in _run_validation_chain
    validator(form, self)
  File "C:\Dev\microblog\app\forms.py", line 43, in validate_username
    user = User.query.filter_by(usename=self.username.data).first()
  File "c:\python36\lib\site-packages\sqlalchemy\orm\query.py", line 1825, in filter_by
    for key, value in kwargs.items()
  File "c:\python36\lib\site-packages\sqlalchemy\orm\query.py", line 1825, in <listcomp>
    for key, value in kwargs.items()
  File "c:\python36\lib\site-packages\sqlalchemy\orm\base.py", line 402, in _entity_descriptor
    "Entity '%s' has no property '%s'" % (description, key)
sqlalchemy.exc.InvalidRequestError: Entity '<class 'app.models.User'>' has no property 'usename'
2020-01-11 15:07:09,942 INFO: Microblog startup [in C:\Dev\microblog\app\__init__.py:41]
2020-01-12 12:10:31,642 INFO: Microblog startup [in C:\Dev\microblog\app\__init__.py:41]
2020-01-12 12:10:44,928 INFO: Microblog startup [in C:\Dev\microblog\app\__init__.py:41]
2020-01-12 12:36:17,663 INFO: Microblog startup [in C:\Dev\microblog\app\__init__.py:41]
2020-01-12 12:38:15,926 INFO: Microblog startup [in C:\Dev\microblog\app\__init__.py:41]
2020-01-12 12:39:59,401 INFO: Microblog startup [in C:\Dev\microblog\app\__init__.py:41]
2020-01-12 17:04:19,966 INFO: Microblog startup [in C:\Dev\microblog\app\__init__.py:41]
2020-01-12 17:04:21,392 ERROR: Exception on / [GET] [in c:\dev\microblog\venv\lib\site-packages\flask\app.py:1891]
Traceback (most recent call last):
  File "c:\dev\microblog\venv\lib\site-packages\sqlalchemy\engine\base.py", line 1246, in _execute_context
    cursor, statement, parameters, context
  File "c:\dev\microblog\venv\lib\site-packages\sqlalchemy\engine\default.py", line 581, in do_execute
    cursor.execute(statement, parameters)
sqlite3.OperationalError: no such table: user

The above exception was the direct cause of the following exception:

Traceback (most recent call last):
  File "c:\dev\microblog\venv\lib\site-packages\flask\app.py", line 2446, in wsgi_app
    response = self.full_dispatch_request()
  File "c:\dev\microblog\venv\lib\site-packages\flask\app.py", line 1951, in full_dispatch_request
    rv = self.handle_user_exception(e)
  File "c:\dev\microblog\venv\lib\site-packages\flask\app.py", line 1820, in handle_user_exception
    reraise(exc_type, exc_value, tb)
  File "c:\dev\microblog\venv\lib\site-packages\flask\_compat.py", line 39, in reraise
    raise value
  File "c:\dev\microblog\venv\lib\site-packages\flask\app.py", line 1947, in full_dispatch_request
    rv = self.preprocess_request()
  File "c:\dev\microblog\venv\lib\site-packages\flask\app.py", line 2241, in preprocess_request
    rv = func()
  File "C:\Dev\microblog\app\routes.py", line 13, in before_request
    if current_user.is_authenticated:
  File "c:\dev\microblog\venv\lib\site-packages\werkzeug\local.py", line 348, in __getattr__
    return getattr(self._get_current_object(), name)
  File "c:\dev\microblog\venv\lib\site-packages\werkzeug\local.py", line 307, in _get_current_object
    return self.__local()
  File "c:\dev\microblog\venv\lib\site-packages\flask_login\utils.py", line 26, in <lambda>
    current_user = LocalProxy(lambda: _get_user())
  File "c:\dev\microblog\venv\lib\site-packages\flask_login\utils.py", line 335, in _get_user
    current_app.login_manager._load_user()
  File "c:\dev\microblog\venv\lib\site-packages\flask_login\login_manager.py", line 359, in _load_user
    return self.reload_user()
  File "c:\dev\microblog\venv\lib\site-packages\flask_login\login_manager.py", line 321, in reload_user
    user = self.user_callback(user_id)
  File "C:\Dev\microblog\app\models.py", line 10, in load_user
    return User.query.get(int(user_id))
  File "c:\dev\microblog\venv\lib\site-packages\sqlalchemy\orm\query.py", line 982, in get
    return self._get_impl(ident, loading.load_on_pk_identity)
  File "c:\dev\microblog\venv\lib\site-packages\sqlalchemy\orm\query.py", line 1094, in _get_impl
    return db_load_fn(self, primary_key_identity)
  File "c:\dev\microblog\venv\lib\site-packages\sqlalchemy\orm\loading.py", line 284, in load_on_pk_identity
    return q.one()
  File "c:\dev\microblog\venv\lib\site-packages\sqlalchemy\orm\query.py", line 3325, in one
    ret = self.one_or_none()
  File "c:\dev\microblog\venv\lib\site-packages\sqlalchemy\orm\query.py", line 3294, in one_or_none
    ret = list(self)
  File "c:\dev\microblog\venv\lib\site-packages\sqlalchemy\orm\query.py", line 3367, in __iter__
    return self._execute_and_instances(context)
  File "c:\dev\microblog\venv\lib\site-packages\sqlalchemy\orm\query.py", line 3392, in _execute_and_instances
    result = conn.execute(querycontext.statement, self._params)
  File "c:\dev\microblog\venv\lib\site-packages\sqlalchemy\engine\base.py", line 982, in execute
    return meth(self, multiparams, params)
  File "c:\dev\microblog\venv\lib\site-packages\sqlalchemy\sql\elements.py", line 287, in _execute_on_connection
    return connection._execute_clauseelement(self, multiparams, params)
  File "c:\dev\microblog\venv\lib\site-packages\sqlalchemy\engine\base.py", line 1101, in _execute_clauseelement
    distilled_params,
  File "c:\dev\microblog\venv\lib\site-packages\sqlalchemy\engine\base.py", line 1250, in _execute_context
    e, statement, parameters, cursor, context
  File "c:\dev\microblog\venv\lib\site-packages\sqlalchemy\engine\base.py", line 1476, in _handle_dbapi_exception
    util.raise_from_cause(sqlalchemy_exception, exc_info)
  File "c:\dev\microblog\venv\lib\site-packages\sqlalchemy\util\compat.py", line 398, in raise_from_cause
    reraise(type(exception), exception, tb=exc_tb, cause=cause)
  File "c:\dev\microblog\venv\lib\site-packages\sqlalchemy\util\compat.py", line 152, in reraise
    raise value.with_traceback(tb)
  File "c:\dev\microblog\venv\lib\site-packages\sqlalchemy\engine\base.py", line 1246, in _execute_context
    cursor, statement, parameters, context
  File "c:\dev\microblog\venv\lib\site-packages\sqlalchemy\engine\default.py", line 581, in do_execute
    cursor.execute(statement, parameters)
sqlalchemy.exc.OperationalError: (sqlite3.OperationalError) no such table: user
[SQL: SELECT user.id AS user_id, user.username AS user_username, user.email AS user_email, user.password_hash AS user_password_hash, user.about_me AS user_about_me, user.last_seen AS user_last_seen 
FROM user 
WHERE user.id = ?]
[parameters: (5,)]
(Background on this error at: http://sqlalche.me/e/e3q8)
