2020-01-11 15:05:30,569 INFO: Microblog startup [in C:\Dev\microblog\app\__init__.py:41]
2020-01-11 15:05:40,965 ERROR: Exception on /edit_profile [POST] [in c:\python36\lib\site-packages\flask\app.py:1891]
Traceback (most recent call last):
  File "c:\python36\lib\site-packages\sqlalchemy\orm\base.py", line 399, in _entity_descriptor
    return getattr(entity, key)
AttributeError: type object 'User' has no attribute 'usename'

During handling of the above exception, another exception occurred:

Traceback (most recent call last):
  File "c:\python36\lib\site-packages\flask\app.py", line 2446, in wsgi_app
    response = self.full_dispatch_request()
  File "c:\python36\lib\site-packages\flask\app.py", line 1951, in full_dispatch_request
    rv = self.handle_user_exception(e)
  File "c:\python36\lib\site-packages\flask\app.py", line 1820, in handle_user_exception
    reraise(exc_type, exc_value, tb)
  File "c:\python36\lib\site-packages\flask\_compat.py", line 39, in reraise
    raise value
  File "c:\python36\lib\site-packages\flask\app.py", line 1949, in full_dispatch_request
    rv = self.dispatch_request()
  File "c:\python36\lib\site-packages\flask\app.py", line 1935, in dispatch_request
    return self.view_functions[rule.endpoint](**req.view_args)
  File "c:\python36\lib\site-packages\flask_login\utils.py", line 261, in decorated_view
    return func(*args, **kwargs)
  File "C:\Dev\microblog\app\routes.py", line 89, in edit_profile
    if form.validate_on_submit():
  File "c:\python36\lib\site-packages\flask_wtf\form.py", line 101, in validate_on_submit
    return self.is_submitted() and self.validate()
  File "c:\python36\lib\site-packages\wtforms\form.py", line 310, in validate
    return super(Form, self).validate(extra)
  File "c:\python36\lib\site-packages\wtforms\form.py", line 152, in validate
    if not field.validate(self, extra):
  File "c:\python36\lib\site-packages\wtforms\fields\core.py", line 206, in validate
    stop_validation = self._run_validation_chain(form, chain)
  File "c:\python36\lib\site-packages\wtforms\fields\core.py", line 226, in _run_validation_chain
    validator(form, self)
  File "C:\Dev\microblog\app\forms.py", line 43, in validate_username
    user = User.query.filter_by(usename=self.username.data).first()
  File "c:\python36\lib\site-packages\sqlalchemy\orm\query.py", line 1825, in filter_by
    for key, value in kwargs.items()
  File "c:\python36\lib\site-packages\sqlalchemy\orm\query.py", line 1825, in <listcomp>
    for key, value in kwargs.items()
  File "c:\python36\lib\site-packages\sqlalchemy\orm\base.py", line 402, in _entity_descriptor
    "Entity '%s' has no property '%s'" % (description, key)
sqlalchemy.exc.InvalidRequestError: Entity '<class 'app.models.User'>' has no property 'usename'
2020-01-11 15:07:09,942 INFO: Microblog startup [in C:\Dev\microblog\app\__init__.py:41]
